[2025-04-20T16:12:21.373+0000] {local_task_job_runner.py:123} INFO - ::group::Pre task execution logs
[2025-04-20T16:12:21.403+0000] {taskinstance.py:2612} INFO - Dependencies all met for dep_context=non-requeueable deps ti=<TaskInstance: extract_stock_data.load_to_snowflake manual__2025-04-20T16:11:41.077299+00:00 [queued]>
[2025-04-20T16:12:21.423+0000] {taskinstance.py:2612} INFO - Dependencies all met for dep_context=requeueable deps ti=<TaskInstance: extract_stock_data.load_to_snowflake manual__2025-04-20T16:11:41.077299+00:00 [queued]>
[2025-04-20T16:12:21.424+0000] {taskinstance.py:2865} INFO - Starting attempt 1 of 1
[2025-04-20T16:12:21.452+0000] {taskinstance.py:2888} INFO - Executing <Task(_PythonDecoratedOperator): load_to_snowflake> on 2025-04-20 16:11:41.077299+00:00
[2025-04-20T16:12:21.473+0000] {logging_mixin.py:190} WARNING - /home/***/.local/lib/python3.12/site-packages/***/task/task_runner/standard_task_runner.py:70 DeprecationWarning: This process (pid=391) is multi-threaded, use of fork() may lead to deadlocks in the child.
[2025-04-20T16:12:21.478+0000] {standard_task_runner.py:72} INFO - Started process 394 to run task
[2025-04-20T16:12:21.474+0000] {standard_task_runner.py:104} INFO - Running: ['***', 'tasks', 'run', 'extract_stock_data', 'load_to_snowflake', 'manual__2025-04-20T16:11:41.077299+00:00', '--job-id', '6', '--raw', '--subdir', 'DAGS_FOLDER/extract_stock_data.py', '--cfg-path', '/tmp/tmpsk9sh8un']
[2025-04-20T16:12:21.481+0000] {standard_task_runner.py:105} INFO - Job 6: Subtask load_to_snowflake
[2025-04-20T16:12:21.586+0000] {task_command.py:467} INFO - Running <TaskInstance: extract_stock_data.load_to_snowflake manual__2025-04-20T16:11:41.077299+00:00 [running]> on host 56370a2e16ce
[2025-04-20T16:12:21.878+0000] {taskinstance.py:3131} INFO - Exporting env vars: AIRFLOW_CTX_DAG_OWNER='***' AIRFLOW_CTX_DAG_ID='extract_stock_data' AIRFLOW_CTX_TASK_ID='load_to_snowflake' AIRFLOW_CTX_EXECUTION_DATE='2025-04-20T16:11:41.077299+00:00' AIRFLOW_CTX_TRY_NUMBER='1' AIRFLOW_CTX_DAG_RUN_ID='manual__2025-04-20T16:11:41.077299+00:00'
[2025-04-20T16:12:21.886+0000] {taskinstance.py:731} INFO - ::endgroup::
[2025-04-20T16:12:21.926+0000] {base.py:84} INFO - Retrieving connection 'snowflake_conn'
[2025-04-20T16:12:21.930+0000] {connection.py:413} INFO - Snowflake Connector for Python Version: 3.12.1, Python Version: 3.12.5, Platform: Linux-5.15.167.4-microsoft-standard-WSL2-x86_64-with-glibc2.36
[2025-04-20T16:12:21.935+0000] {connection.py:1196} INFO - Connecting to GLOBAL Snowflake domain
[2025-04-20T16:12:21.937+0000] {connection.py:1277} INFO - This connection is in OCSP Fail Open Mode. TLS Certificates would be checked for validity and revocation status. Any other Certificate Revocation related exceptions or OCSP Responder failures would be disregarded in favor of connectivity.
[2025-04-20T16:12:24.219+0000] {cursor.py:1156} INFO - Number of results in first chunk: 1
[2025-04-20T16:12:24.448+0000] {cursor.py:1156} INFO - Number of results in first chunk: 1
[2025-04-20T16:12:24.943+0000] {cursor.py:1156} INFO - Number of results in first chunk: 1
[2025-04-20T16:12:25.066+0000] {base.py:84} INFO - Retrieving connection 'snowflake_conn'
[2025-04-20T16:12:25.076+0000] {connection.py:413} INFO - Snowflake Connector for Python Version: 3.12.1, Python Version: 3.12.5, Platform: Linux-5.15.167.4-microsoft-standard-WSL2-x86_64-with-glibc2.36
[2025-04-20T16:12:25.091+0000] {connection.py:1196} INFO - Connecting to GLOBAL Snowflake domain
[2025-04-20T16:12:25.101+0000] {connection.py:1277} INFO - This connection is in OCSP Fail Open Mode. TLS Certificates would be checked for validity and revocation status. Any other Certificate Revocation related exceptions or OCSP Responder failures would be disregarded in favor of connectivity.
[2025-04-20T16:12:26.838+0000] {cursor.py:1156} INFO - Number of results in first chunk: 1
[2025-04-20T16:12:26.884+0000] {sql.py:509} INFO - Running statement: PUT 'file:///tmp/AAPL_data.csv' @USER_DB_GRIZZLY.GRIZZLY_RAW.stock_stage/AAPL_data.csv AUTO_COMPRESS=TRUE OVERWRITE=TRUE, parameters: None
[2025-04-20T16:12:28.041+0000] {sql.py:518} INFO - Rows affected: 1
[2025-04-20T16:12:28.044+0000] {snowflake.py:422} INFO - Rows affected: 1
[2025-04-20T16:12:28.046+0000] {snowflake.py:423} INFO - Snowflake query id: 01bbd18c-0305-0010-0004-59ff0023655a
[2025-04-20T16:12:28.118+0000] {cursor.py:1156} INFO - Number of results in first chunk: 1
[2025-04-20T16:12:28.120+0000] {connection.py:788} INFO - closed
[2025-04-20T16:12:28.182+0000] {connection.py:794} INFO - No async queries seem to be running, deleting session
[2025-04-20T16:12:28.498+0000] {cursor.py:1156} INFO - Number of results in first chunk: 1
[2025-04-20T16:12:29.612+0000] {cursor.py:1156} INFO - Number of results in first chunk: 1
[2025-04-20T16:12:31.262+0000] {cursor.py:1156} INFO - Number of results in first chunk: 1
[2025-04-20T16:12:31.271+0000] {connection.py:413} INFO - Snowflake Connector for Python Version: 3.12.1, Python Version: 3.12.5, Platform: Linux-5.15.167.4-microsoft-standard-WSL2-x86_64-with-glibc2.36
[2025-04-20T16:12:31.273+0000] {connection.py:1196} INFO - Connecting to GLOBAL Snowflake domain
[2025-04-20T16:12:31.275+0000] {connection.py:1277} INFO - This connection is in OCSP Fail Open Mode. TLS Certificates would be checked for validity and revocation status. Any other Certificate Revocation related exceptions or OCSP Responder failures would be disregarded in favor of connectivity.
[2025-04-20T16:12:31.681+0000] {cursor.py:1156} INFO - Number of results in first chunk: 1
[2025-04-20T16:12:31.683+0000] {sql.py:509} INFO - Running statement: PUT 'file:///tmp/NVDA_data.csv' @USER_DB_GRIZZLY.GRIZZLY_RAW.stock_stage/NVDA_data.csv AUTO_COMPRESS=TRUE OVERWRITE=TRUE, parameters: None
[2025-04-20T16:12:31.924+0000] {connection.py:788} INFO - closed
[2025-04-20T16:12:31.995+0000] {connection.py:794} INFO - No async queries seem to be running, deleting session
[2025-04-20T16:12:32.155+0000] {cursor.py:1156} INFO - Number of results in first chunk: 1
[2025-04-20T16:12:32.157+0000] {logging_mixin.py:190} INFO - Error loading data to Snowflake: 253006: 253006: File doesn't exist: ['/tmp/NVDA_data.csv']
[2025-04-20T16:12:32.159+0000] {taskinstance.py:3310} ERROR - Task failed with exception
Traceback (most recent call last):
  File "/home/airflow/.local/lib/python3.12/site-packages/airflow/models/taskinstance.py", line 767, in _execute_task
    result = _execute_callable(context=context, **execute_callable_kwargs)
             ^^^^^^^^^^^^^^^^^^^^^^^^^^^^^^^^^^^^^^^^^^^^^^^^^^^^^^^^^^^^^
  File "/home/airflow/.local/lib/python3.12/site-packages/airflow/models/taskinstance.py", line 733, in _execute_callable
    return ExecutionCallableRunner(
           ^^^^^^^^^^^^^^^^^^^^^^^^
  File "/home/airflow/.local/lib/python3.12/site-packages/airflow/utils/operator_helpers.py", line 252, in run
    return self.func(*args, **kwargs)
           ^^^^^^^^^^^^^^^^^^^^^^^^^^
  File "/home/airflow/.local/lib/python3.12/site-packages/airflow/models/baseoperator.py", line 406, in wrapper
    return func(self, *args, **kwargs)
           ^^^^^^^^^^^^^^^^^^^^^^^^^^^
  File "/home/airflow/.local/lib/python3.12/site-packages/airflow/decorators/base.py", line 266, in execute
    return_value = super().execute(context)
                   ^^^^^^^^^^^^^^^^^^^^^^^^
  File "/home/airflow/.local/lib/python3.12/site-packages/airflow/models/baseoperator.py", line 406, in wrapper
    return func(self, *args, **kwargs)
           ^^^^^^^^^^^^^^^^^^^^^^^^^^^
  File "/home/airflow/.local/lib/python3.12/site-packages/airflow/operators/python.py", line 238, in execute
    return_value = self.execute_callable()
                   ^^^^^^^^^^^^^^^^^^^^^^^
  File "/home/airflow/.local/lib/python3.12/site-packages/airflow/operators/python.py", line 256, in execute_callable
    return runner.run(*self.op_args, **self.op_kwargs)
           ^^^^^^^^^^^^^^^^^^^^^^^^^^^^^^^^^^^^^^^^^^^
  File "/home/airflow/.local/lib/python3.12/site-packages/airflow/utils/operator_helpers.py", line 252, in run
    return self.func(*args, **kwargs)
           ^^^^^^^^^^^^^^^^^^^^^^^^^^
  File "/opt/airflow/dags/extract_stock_data.py", line 72, in load_to_snowflake
    hook.run(f"PUT 'file://{file_path}' @{SNOWFLAKE_STAGE}/{file_name} AUTO_COMPRESS=TRUE OVERWRITE=TRUE")
  File "/home/airflow/.local/lib/python3.12/site-packages/airflow/providers/snowflake/hooks/snowflake.py", line 410, in run
    self._run_command(cur, sql_statement, parameters)  # type: ignore[attr-defined]
    ^^^^^^^^^^^^^^^^^^^^^^^^^^^^^^^^^^^^^^^^^^^^^^^^^
  File "/home/airflow/.local/lib/python3.12/site-packages/airflow/providers/common/sql/hooks/sql.py", line 514, in _run_command
    cur.execute(sql_statement)
  File "/home/airflow/.local/lib/python3.12/site-packages/snowflake/connector/cursor.py", line 1053, in execute
    sf_file_transfer_agent.execute()
  File "/home/airflow/.local/lib/python3.12/site-packages/snowflake/connector/file_transfer_agent.py", line 390, in execute
    self._init_file_metadata()
  File "/home/airflow/.local/lib/python3.12/site-packages/snowflake/connector/file_transfer_agent.py", line 986, in _init_file_metadata
    Error.errorhandler_wrapper(
  File "/home/airflow/.local/lib/python3.12/site-packages/snowflake/connector/errors.py", line 284, in errorhandler_wrapper
    handed_over = Error.hand_to_other_handler(
                  ^^^^^^^^^^^^^^^^^^^^^^^^^^^^
  File "/home/airflow/.local/lib/python3.12/site-packages/snowflake/connector/errors.py", line 339, in hand_to_other_handler
    cursor.errorhandler(connection, cursor, error_class, error_value)
  File "/home/airflow/.local/lib/python3.12/site-packages/snowflake/connector/errors.py", line 215, in default_errorhandler
    raise error_class(
snowflake.connector.errors.ProgrammingError: 253006: 253006: File doesn't exist: ['/tmp/NVDA_data.csv']
[2025-04-20T16:12:32.221+0000] {taskinstance.py:1225} INFO - Marking task as FAILED. dag_id=extract_stock_data, task_id=load_to_snowflake, run_id=manual__2025-04-20T16:11:41.077299+00:00, execution_date=20250420T161141, start_date=20250420T161221, end_date=20250420T161232
[2025-04-20T16:12:32.325+0000] {taskinstance.py:340} INFO - ::group::Post task execution logs
[2025-04-20T16:12:32.336+0000] {standard_task_runner.py:124} ERROR - Failed to execute job 6 for task load_to_snowflake (253006: 253006: File doesn't exist: ['/tmp/NVDA_data.csv']; 394)
Traceback (most recent call last):
  File "/home/airflow/.local/lib/python3.12/site-packages/airflow/task/task_runner/standard_task_runner.py", line 117, in _start_by_fork
    ret = args.func(args, dag=self.dag)
          ^^^^^^^^^^^^^^^^^^^^^^^^^^^^^
  File "/home/airflow/.local/lib/python3.12/site-packages/airflow/cli/cli_config.py", line 49, in command
    return func(*args, **kwargs)
           ^^^^^^^^^^^^^^^^^^^^^
  File "/home/airflow/.local/lib/python3.12/site-packages/airflow/utils/cli.py", line 115, in wrapper
    return f(*args, **kwargs)
           ^^^^^^^^^^^^^^^^^^
  File "/home/airflow/.local/lib/python3.12/site-packages/airflow/cli/commands/task_command.py", line 483, in task_run
    task_return_code = _run_task_by_selected_method(args, _dag, ti)
                       ^^^^^^^^^^^^^^^^^^^^^^^^^^^^^^^^^^^^^^^^^^^^
  File "/home/airflow/.local/lib/python3.12/site-packages/airflow/cli/commands/task_command.py", line 256, in _run_task_by_selected_method
    return _run_raw_task(args, ti)
           ^^^^^^^^^^^^^^^^^^^^^^^
  File "/home/airflow/.local/lib/python3.12/site-packages/airflow/cli/commands/task_command.py", line 341, in _run_raw_task
    return ti._run_raw_task(
           ^^^^^^^^^^^^^^^^^
  File "/home/airflow/.local/lib/python3.12/site-packages/airflow/utils/session.py", line 97, in wrapper
    return func(*args, session=session, **kwargs)
           ^^^^^^^^^^^^^^^^^^^^^^^^^^^^^^^^^^^^^^
  File "/home/airflow/.local/lib/python3.12/site-packages/airflow/models/taskinstance.py", line 3004, in _run_raw_task
    return _run_raw_task(
           ^^^^^^^^^^^^^^
  File "/home/airflow/.local/lib/python3.12/site-packages/airflow/models/taskinstance.py", line 273, in _run_raw_task
    TaskInstance._execute_task_with_callbacks(
  File "/home/airflow/.local/lib/python3.12/site-packages/airflow/models/taskinstance.py", line 3158, in _execute_task_with_callbacks
    result = self._execute_task(context, task_orig)
             ^^^^^^^^^^^^^^^^^^^^^^^^^^^^^^^^^^^^^^
  File "/home/airflow/.local/lib/python3.12/site-packages/airflow/models/taskinstance.py", line 3182, in _execute_task
    return _execute_task(self, context, task_orig)
           ^^^^^^^^^^^^^^^^^^^^^^^^^^^^^^^^^^^^^^^
  File "/home/airflow/.local/lib/python3.12/site-packages/airflow/models/taskinstance.py", line 767, in _execute_task
    result = _execute_callable(context=context, **execute_callable_kwargs)
             ^^^^^^^^^^^^^^^^^^^^^^^^^^^^^^^^^^^^^^^^^^^^^^^^^^^^^^^^^^^^^
  File "/home/airflow/.local/lib/python3.12/site-packages/airflow/models/taskinstance.py", line 733, in _execute_callable
    return ExecutionCallableRunner(
           ^^^^^^^^^^^^^^^^^^^^^^^^
  File "/home/airflow/.local/lib/python3.12/site-packages/airflow/utils/operator_helpers.py", line 252, in run
    return self.func(*args, **kwargs)
           ^^^^^^^^^^^^^^^^^^^^^^^^^^
  File "/home/airflow/.local/lib/python3.12/site-packages/airflow/models/baseoperator.py", line 406, in wrapper
    return func(self, *args, **kwargs)
           ^^^^^^^^^^^^^^^^^^^^^^^^^^^
  File "/home/airflow/.local/lib/python3.12/site-packages/airflow/decorators/base.py", line 266, in execute
    return_value = super().execute(context)
                   ^^^^^^^^^^^^^^^^^^^^^^^^
  File "/home/airflow/.local/lib/python3.12/site-packages/airflow/models/baseoperator.py", line 406, in wrapper
    return func(self, *args, **kwargs)
           ^^^^^^^^^^^^^^^^^^^^^^^^^^^
  File "/home/airflow/.local/lib/python3.12/site-packages/airflow/operators/python.py", line 238, in execute
    return_value = self.execute_callable()
                   ^^^^^^^^^^^^^^^^^^^^^^^
  File "/home/airflow/.local/lib/python3.12/site-packages/airflow/operators/python.py", line 256, in execute_callable
    return runner.run(*self.op_args, **self.op_kwargs)
           ^^^^^^^^^^^^^^^^^^^^^^^^^^^^^^^^^^^^^^^^^^^
  File "/home/airflow/.local/lib/python3.12/site-packages/airflow/utils/operator_helpers.py", line 252, in run
    return self.func(*args, **kwargs)
           ^^^^^^^^^^^^^^^^^^^^^^^^^^
  File "/opt/airflow/dags/extract_stock_data.py", line 72, in load_to_snowflake
    hook.run(f"PUT 'file://{file_path}' @{SNOWFLAKE_STAGE}/{file_name} AUTO_COMPRESS=TRUE OVERWRITE=TRUE")
  File "/home/airflow/.local/lib/python3.12/site-packages/airflow/providers/snowflake/hooks/snowflake.py", line 410, in run
    self._run_command(cur, sql_statement, parameters)  # type: ignore[attr-defined]
    ^^^^^^^^^^^^^^^^^^^^^^^^^^^^^^^^^^^^^^^^^^^^^^^^^
  File "/home/airflow/.local/lib/python3.12/site-packages/airflow/providers/common/sql/hooks/sql.py", line 514, in _run_command
    cur.execute(sql_statement)
  File "/home/airflow/.local/lib/python3.12/site-packages/snowflake/connector/cursor.py", line 1053, in execute
    sf_file_transfer_agent.execute()
  File "/home/airflow/.local/lib/python3.12/site-packages/snowflake/connector/file_transfer_agent.py", line 390, in execute
    self._init_file_metadata()
  File "/home/airflow/.local/lib/python3.12/site-packages/snowflake/connector/file_transfer_agent.py", line 986, in _init_file_metadata
    Error.errorhandler_wrapper(
  File "/home/airflow/.local/lib/python3.12/site-packages/snowflake/connector/errors.py", line 284, in errorhandler_wrapper
    handed_over = Error.hand_to_other_handler(
                  ^^^^^^^^^^^^^^^^^^^^^^^^^^^^
  File "/home/airflow/.local/lib/python3.12/site-packages/snowflake/connector/errors.py", line 339, in hand_to_other_handler
    cursor.errorhandler(connection, cursor, error_class, error_value)
  File "/home/airflow/.local/lib/python3.12/site-packages/snowflake/connector/errors.py", line 215, in default_errorhandler
    raise error_class(
snowflake.connector.errors.ProgrammingError: 253006: 253006: File doesn't exist: ['/tmp/NVDA_data.csv']
[2025-04-20T16:12:32.456+0000] {local_task_job_runner.py:266} INFO - Task exited with return code 1
[2025-04-20T16:12:32.595+0000] {taskinstance.py:3900} INFO - 0 downstream tasks scheduled from follow-on schedule check
[2025-04-20T16:12:32.611+0000] {local_task_job_runner.py:245} INFO - ::endgroup::
